Workbook

Sheet Raw_Data
A1: customer_id | B1: full_name | C1: gender | D1: birth_date | E1: phone | F1: email | G1: city | H1: region | I1: loyalty_tier | J1: registration_date
A2: CUS01518 | B2: Mohamed Mansour | C2: Male | D2: 29707 | E2: 1158132110 | F2: mohamed.mansour52@hotmail.com | G2: Suez | H2: Canal Zone | I2: Bronze | J2: 44184
A3: CUS02370 | B3: Maged Lotfy | C3: Male | D3: 37721 | E3: 1281872177 | G3: Zagazig | H3: Nile Delta | I3: Bronze | J3: 44329
A4: CUS01962 | B4: Ahmed Hafez | C4: MALE | D4: 26056 | E4: 1141856715 | F4: ahmed.hafez18@outlook.com | G4: Giza | H4: Greater Cairo | I4: Gold | J4: 45195
A5: CUS00344 | B5: Hoda Fathy | C5: female | D5: 36665 | E5: 1195645083 | F5: hoda.fathy26@outlook.com | G5: Giza | H5: Greater Cairo | I5: Bronze | J5: 44384
A6: CUS02664 | B6: Hussein Lotfy | C6: MALE | D6: 36155 | E6: 1149528740 | F6: hussein.lotfy80@gmail.com | G6: Tanta | H6: Nile Delta | I6: gold | J6: 44839
A7: CUS01174 | B7: Nour Mostafa | C7: Female | D7: 30843 | E7: 1114481563 | F7: nour.mostafa72@hotmail.com | G7: Cairo | H7: Greater Cairo | I7: SILVER | J7: 44476
A8: CUS02677 | B8: Hazem Hamdy | C8: MALE | D8: 27297 | E8: 1084698064 | F8: hazem.hamdy68@outlook.com | G8: Giza | H8: Greater Cairo | I8: Bronze | J8: 43858
A9: CUS01028 | B9: Fatima Ramadan | C9: Female | D9: 27687 | E9: 1019232076 | F9: fatima.ramadan42@outlook.com | G9: Aswan | H9: Upper Egypt | I9: Bronze | J9: 45019
A10: CUS02084 | B10: Ramy Farouk | C10: male | E10: 1069113227 | G10: Suez | H10: Canal Zone | I10: Silver | J10: 44448
A11: CUS01445 | B11: Sherif Zaki | C11: Male | D11: 33609 | F11: sherif.zaki7@hotmail.com | G11: Luxor | H11: Upper Egypt | I11: Silver | J11: 44129
A12: CUS00933 | C12: Male | D12: 33225 | E12: 1229438263 | F12: bassem.farouk40@gmail.com | G12: Ismailia | H12: Canal Zone | I12: Silver | J12: 44191
A13: CUS00179 | B13: Hossam Fathy | C13: male | D13: 29867 | E13: 1248988647 | F13: hossam.fathy16@yahoo.com | G13: Port Said | I13: Bronze | J13: 45109
A14: CUS01594 | B14: Hoda Badawi | C14: Female | D14: 14/11/1985 | E14: 1271886181 | F14: hoda.badawi40@yahoo.com | G14: Cairo | H14: Greater Cairo | I14: Gold | J14: 44701
A15: CUS01948 | B15: Ahmed Mostafa | C15: male | D15: 1980-12-01 | E15: 1070428122 | F15: ahmed.mostafa83@hotmail.com | G15: Cairo | H15: Greater Cairo | I15: Platinum | J15: 44762
A16: CUS01663 | B16: Yasmin Khalil | C16: Female | E16: 1078622351 | F16: yasmin.khalil15@gmail.com | G16: Suez | H16: Canal Zone | I16: Silver | J16: 11/23/2023
A17: CUS02432 | B17: Hussein Younis | C17: Male | D17: 34676 | E17: 1224467198 | F17: hussein.younis30@yahoo.com | G17: Aswan | H17: Upper Egypt | I17: Bronze | J17: not a date
A18: CUS02863 | B18: Ramy Ramadan | C18: UnknownGender | D18: 32650 | E18: 1019329244 | F18: ramy.ramadan58@yahoo.com | G18: Port Said | H18: Canal Zone | I18: Platinum | J18: 45035
A19: CUS02343 | B19: Doha Shaaban | C19: Female | D19: 35936 | E19: 1093235590 | F19: doha.shaaban46@gmail.com | G19: Cairo | H19: Greater Cairo | I19: Platinum | J19: 44792
A20: CUS01498 | B20: Tarek Ragab | C20: Male | D20: 27080 | E20: 1290242618 | F20: tarek.ragab11@gmail.com | G20: Alexandria | H20: Alexandria | I20: Silver | J20: 44146
A21: CUS02967 | B21: Ibrahim Bakr | C21: Male | D21: 29300 | E21: 1221940949 | F21: ibrahim.bakr8@outlook.com | G21: Zagazig | H21: Nile Delta | I21: Platinum | J21: 44486
A22: CUS02414 | B22: Salma Zaki | C22: FEMALE | D22: 28252 | E22: 1095240437 | F22: salma.zaki23@hotmail.com | G22: Cairo | H22: Greater Cairo | I22: Bronze | J22: 45177
A23: CUS02808 | B23: Ramy Ali | C23: Male | D23: 34985 | E23: 1225235645 | F23: ramy.ali33@hotmail.com | G23: Cairo | H23: Greater Cairo | I23: Bronze | J23: 44627
A24: CUS01284 | B24: Hany Khalil | C24: Male | D24: 35454 | E24: 1258398175 | F24: hany.khalil59@outlook.com | G24: Cairo | H24: Greater Cairo | I24: Bronze | J24: 45063
A25: CUS02869 | B25: Engy Attia | C25: Female | E25: 1027978174 | F25: engy.attia68@yahoo.com | G25: Giza | H25: Greater Cairo | I25: Bronze | J25: 43837
A26: CUS00890 | B26: Tarek Lotfy | C26: Male | D26: 32574 | E26: 1044810342 | G26: Cairo | H26: Greater Cairo | I26: Bronze | J26: 44940
A27: CUS01460 | B27: Nour Bakr | C27: Female | D27: 29284 | E27: 1126675052 | F27: nour.bakr54@hotmail.com | G27: Mansoura | H27: Nile Delta | I27: Silver | J27: 44094
A28: CUS00652 | B28: Ramy Mansour | C28: MALE | D28: 35566 | E28: 1034772080 | F28: ramy.mansour11@hotmail.com | G28: Alexandria | H28: Alexandria | I28: Bronze | J28: 44974
A29: CUS01437 | B29: Yasmin Abdallah | C29: Female | D29: 35285 | E29: 1223416165 | F29: yasmin.abdallah68@gmail.com | G29: Giza | H29: Greater Cairo | I29: Gold | J29: 44816
A30: CUS00555 | B30: Omar Ahmed | C30: Male | D30: 28759 | E30: 1167096991 | G30: Luxor | H30: Upper Egypt | I30: Bronze | J30: 45132
A31: CUS02264 | B31: Hussein Hassan | C31: male | D31: 28380 | E31: 1216614286 | F31: hussein.hassan95@hotmail.com | G31: Giza | H31: Greater Cairo | I31: Silver | J31: 44585
A32: CUS00440 | B32: Ahmed Zaki | C32: male | D32: 30201 | E32: 1214344197 | G32: Cairo | H32: Greater Cairo | I32: Bronze | J32: 44928
A33: CUS02568 | B33: Rana Ismail | C33: female | D33: 34344 | E33: 1046060709 | F33: rana.ismail64@gmail.com | G33: Giza | H33: Greater Cairo | I33: Gold | J33: 44243
A34: CUS01042 | B34: Amr Salem | C34: Male | D34: 37096 | E34: 1143524010 | F34: amr.salem38@yahoo.com | G34: Hurghada | H34: Red Sea | I34: Bronze | J34: 44240
A35: CUS01227 | B35: Fady Lotfy | C35: male | D35: 32591 | E35: 1228177418 | F35: fady.lotfy20@gmail.com | G35: Giza | H35: Greater Cairo | I35: Gold | J35: 44297
A36: CUS00189 | B36: Dina Attia | C36: Female | D36: 28548 | E36: 1272850928 | F36: dina.attia61@yahoo.com | G36: Alexandria | H36: Alexandria | I36: Gold | J36: 44283
A37: CUS01780 | B37: Sherif Hamdy | C37: Male | D37: 36205 | E37: 1164024116 | G37: Aswan | H37: Upper Egypt | I37: Silver | J37: 43837
A38: CUS00496 | B38: Nadia Badawi | C38: Female | D38: 28311 | E38: 1212906871 | F38: nadia.badawi95@yahoo.com | G38: Giza | H38: Greater Cairo | I38: Bronze | J38: 45148
A39: CUS00791 | B39: Ibrahim Hamdy | C39: Male | D39: 33067 | E39: 1279641006 | F39: ibrahim.hamdy27@outlook.com | G39: Cairo | H39: Greater Cairo | I39: Silver | J39: 44679
A40: CUS00573 | B40: Manar Ibrahim | C40: Female | D40: 33838 | E40: 1288709162 | F40: manar.ibrahim47@hotmail.com | G40: Giza | H40: Greater Cairo | I40: Silver | J40: 44124
...

Sheet Clean_Data
A1: Source_Row | B1: Customer_ID_Clean | C1: Full_Name_Clean | D1: Gender_Clean | E1: Birth_Date_Clean | F1: Phone_Clean | G1: Email_Clean | H1: City_Clean | I1: Region_Clean | J1: Loyalty_Tier_Clean | K1: Registration_Date_Clean | L1: Email_Domain | M1: ID_Prefix | N1: ID_Number | O1: Phone_Last4 | P1: Display_Label | Q1: Record_Status | R1: Keep_Record
A2: =ROW(Raw_Data!A2) -> 2 | B2: =TRIM(CLEAN(Raw_Data!A2)) -> CUS01518 | C2: =IF(TRIM(CLEAN(Raw_Data!B2))="","Not Provided",PROPER(TRIM(CLEAN(Raw_Data!B2)))) -> Mohamed Mansour | D2: =IF(OR(PROPER(TRIM(CLEAN(Raw_Data!C2)))="Male",PROPER(TRIM(CLEAN(Raw_Data!C2)))="Female"),PROPER(TRIM(CLEAN(Raw_Data!C2))),"Unknown") -> Male | E2: =IF(ISNUMBER(Raw_Data!D2),Raw_Data!D2,IFERROR(DATEVALUE(Raw_Data!D2),"")) -> 29707 | F2: =IF(TRIM(CLEAN(Raw_Data!E2))="","Not Provided",TRIM(CLEAN(Raw_Data!E2))) -> 1158132110 | G2: =IF(TRIM(CLEAN(Raw_Data!F2))="","Not Provided",LOWER(TRIM(CLEAN(Raw_Data!F2)))) -> mohamed.mansour52@hotmail.com | H2: =IF(TRIM(CLEAN(Raw_Data!G2))="","Not Provided",PROPER(TRIM(CLEAN(Raw_Data!G2)))) -> Suez | I2: =IF(TRIM(CLEAN(Raw_Data!H2))="","Not Provided",PROPER(TRIM(CLEAN(Raw_Data!H2)))) -> Canal Zone | J2: =IF(OR(PROPER(TRIM(CLEAN(Raw_Data!I2)))="Bronze",PROPER(TRIM(CLEAN(Raw_Data!I2)))="Silver",PROPER(TRIM(CLEAN(Raw_Data!I2)))="Gold"),PROPER(TRIM(CLEAN(Raw_Data!I2))),"Unknown") -> Bronze | K2: =IF(ISNUMBER(Raw_Data!J2),Raw_Data!J2,IFERROR(DATEVALUE(Raw_Data!J2),"")) -> 44184 | L2: =IFERROR(MID(G2,FIND("@",G2)+1,99),"") -> hotmail.com | M2: =LEFT(B2,3) -> CUS | N2: =IFERROR(MID(B2,4,10),"") -> 01518 | O2: =RIGHT(F2,4) -> 2110 | P2: =CONCATENATE(C2," - ",J2) -> Mohamed Mansour - Bronze | Q2: =IF(B2="","Remove - missing ID",IF(OR(E2="",K2=""),"Remove - invalid date",IF(COUNTIF($B$2:B2,B2)>1,"Remove - duplicate ID","Keep"))) -> Keep | R2: =IF(Q2="Keep","Yes","No") -> Yes
A3: =ROW(Raw_Data!A3) -> 3 | B3: =TRIM(CLEAN(Raw_Data!A3)) -> CUS02370 | C3: =IF(TRIM(CLEAN(Raw_Data!B3))="","Not Provided",PROPER(TRIM(CLEAN(Raw_Data!B3)))) -> Maged Lotfy | D3: =IF(OR(PROPER(TRIM(CLEAN(Raw_Data!C3)))="Male",PROPER(TRIM(CLEAN(Raw_Data!C3)))="Female"),PROPER(TRIM(CLEAN(Raw_Data!C3))),"Unknown") -> Male | E3: =IF(ISNUMBER(Raw_Data!D3),Raw_Data!D3,IFERROR(DATEVALUE(Raw_Data!D3),"")) -> 37721 | F3: =IF(TRIM(CLEAN(Raw_Data!E3))="","Not Provided",TRIM(CLEAN(Raw_Data!E3))) -> 1281872177 | G3: =IF(TRIM(CLEAN(Raw_Data!F3))="","Not Provided",LOWER(TRIM(CLEAN(Raw_Data!F3)))) -> Not Provided | H3: =IF(TRIM(CLEAN(Raw_Data!G3))="","Not Provided",PROPER(TRIM(CLEAN(Raw_Data!G3)))) -> Zagazig | I3: =IF(TRIM(CLEAN(Raw_Data!H3))="","Not Provided",PROPER(TRIM(CLEAN(Raw_Data!H3)))) -> Nile Delta | J3: =IF(OR(PROPER(TRIM(CLEAN(Raw_Data!I3)))="Bronze",PROPER(TRIM(CLEAN(Raw_Data!I3)))="Silver",PROPER(TRIM(CLEAN(Raw_Data!I3)))="Gold"),PROPER(TRIM(CLEAN(Raw_Data!I3))),"Unknown") -> Bronze | K3: =IF(ISNUMBER(Raw_Data!J3),Raw_Data!J3,IFERROR(DATEVALUE(Raw_Data!J3),"")) -> 44329 | L3: =IFERROR(MID(G3,FIND("@",G3)+1,99),"") | M3: =LEFT(B3,3) -> CUS | N3: =IFERROR(MID(B3,4,10),"") -> 02370 | O3: =RIGHT(F3,4) -> 2177 | P3: =CONCATENATE(C3," - ",J3) -> Maged Lotfy - Bronze | Q3: =IF(B3="","Remove - missing ID",IF(OR(E3="",K3=""),"Remove - invalid date",IF(COUNTIF($B$2:B3,B3)>1,"Remove - duplicate ID","Keep"))) -> Keep | R3: =IF(Q3="Keep","Yes","No") -> Yes
A4: =ROW(Raw_Data!A4) -> 4 | B4: =TRIM(CLEAN(Raw_Data!A4)) -> CUS01962 | C4: =IF(TRIM(CLEAN(Raw_Data!B4))="","Not Provided",PROPER(TRIM(CLEAN(Raw_Data!B4)))) -> Ahmed Hafez | D4: =IF(OR(PROPER(TRIM(CLEAN(Raw_Data!C4)))="Male",PROPER(TRIM(CLEAN(Raw_Data!C4)))="Female"),PROPER(TRIM(CLEAN(Raw_Data!C4))),"Unknown") -> Male | E4: =IF(ISNUMBER(Raw_Data!D4),Raw_Data!D4,IFERROR(DATEVALUE(Raw_Data!D4),"")) -> 26056 | F4: =IF(TRIM(CLEAN(Raw_Data!E4))="","Not Provided",TRIM(CLEAN(Raw_Data!E4))) -> 1141856715 | G4: =IF(TRIM(CLEAN(Raw_Data!F4))="","Not Provided",LOWER(TRIM(CLEAN(Raw_Data!F4)))) -> ahmed.hafez18@outlook.com | H4: =IF(TRIM(CLEAN(Raw_Data!G4))="","Not Provided",PROPER(TRIM(CLEAN(Raw_Data!G4)))) -> Giza | I4: =IF(TRIM(CLEAN(Raw_Data!H4))="","Not Provided",PROPER(TRIM(CLEAN(Raw_Data!H4)))) -> Greater Cairo | J4: =IF(OR(PROPER(TRIM(CLEAN(Raw_Data!I4)))="Bronze",PROPER(TRIM(CLEAN(Raw_Data!I4)))="Silver",PROPER(TRIM(CLEAN(Raw_Data!I4)))="Gold"),PROPER(TRIM(CLEAN(Raw_Data!I4))),"Unknown") -> Gold | K4: =IF(ISNUMBER(Raw_Data!J4),Raw_Data!J4,IFERROR(DATEVALUE(Raw_Data!J4),"")) -> 45195 | L4: =IFERROR(MID(G4,FIND("@",G4)+1,99),"") -> outlook.com | M4: =LEFT(B4,3) -> CUS | N4: =IFERROR(MID(B4,4,10),"") -> 01962 | O4: =RIGHT(F4,4) -> 6715 | P4: =CONCATENATE(C4," - ",J4) -> Ahmed Hafez - Gold | Q4: =IF(B4="","Remove - missing ID",IF(OR(E4="",K4=""),"Remove - invalid date",IF(COUNTIF($B$2:B4,B4)>1,"Remove - duplicate ID","Keep"))) -> Keep | R4: =IF(Q4="Keep","Yes","No") -> Yes
A5: =ROW(Raw_Data!A5) -> 5 | B5: =TRIM(CLEAN(Raw_Data!A5)) -> CUS00344 | C5: =IF(TRIM(CLEAN(Raw_Data!B5))="","Not Provided",PROPER(TRIM(CLEAN(Raw_Data!B5)))) -> Hoda Fathy | D5: =IF(OR(PROPER(TRIM(CLEAN(Raw_Data!C5)))="Male",PROPER(TRIM(CLEAN(Raw_Data!C5)))="Female"),PROPER(TRIM(CLEAN(Raw_Data!C5))),"Unknown") -> Female | E5: =IF(ISNUMBER(Raw_Data!D5),Raw_Data!D5,IFERROR(DATEVALUE(Raw_Data!D5),"")) -> 36665 | F5: =IF(TRIM(CLEAN(Raw_Data!E5))="","Not Provided",TRIM(CLEAN(Raw_Data!E5))) -> 1195645083 | G5: =IF(TRIM(CLEAN(Raw_Data!F5))="","Not Provided",LOWER(TRIM(CLEAN(Raw_Data!F5)))) -> hoda.fathy26@outlook.com | H5: =IF(TRIM(CLEAN(Raw_Data!G5))="","Not Provided",PROPER(TRIM(CLEAN(Raw_Data!G5)))) -> Giza | I5: =IF(TRIM(CLEAN(Raw_Data!H5))="","Not Provided",PROPER(TRIM(CLEAN(Raw_Data!H5)))) -> Greater Cairo | J5: =IF(OR(PROPER(TRIM(CLEAN(Raw_Data!I5)))="Bronze",PROPER(TRIM(CLEAN(Raw_Data!I5)))="Silver",PROPER(TRIM(CLEAN(Raw_Data!I5)))="Gold"),PROPER(TRIM(CLEAN(Raw_Data!I5))),"Unknown") -> Bronze | K5: =IF(ISNUMBER(Raw_Data!J5),Raw_Data!J5,IFERROR(DATEVALUE(Raw_Data!J5),"")) -> 44384 | L5: =IFERROR(MID(G5,FIND("@",G5)+1,99),"") -> outlook.com | M5: =LEFT(B5,3) -> CUS | N5: =IFERROR(MID(B5,4,10),"") -> 00344 | O5: =RIGHT(F5,4) -> 5083 | P5: =CONCATENATE(C5," - ",J5) -> Hoda Fathy - Bronze | Q5: =IF(B5="","Remove - missing ID",IF(OR(E5="",K5=""),"Remove - invalid date",IF(COUNTIF($B$2:B5,B5)>1,"Remove - duplicate ID","Keep"))) -> Keep | R5: =IF(Q5="Keep","Yes","No") -> Yes
A6: =ROW(Raw_Data!A6) -> 6 | B6: =TRIM(CLEAN(Raw_Data!A6)) -> CUS02664 | C6: =IF(TRIM(CLEAN(Raw_Data!B6))="","Not Provided",PROPER(TRIM(CLEAN(Raw_Data!B6)))) -> Hussein Lotfy | D6: =IF(OR(PROPER(TRIM(CLEAN(Raw_Data!C6)))="Male",PROPER(TRIM(CLEAN(Raw_Data!C6)))="Female"),PROPER(TRIM(CLEAN(Raw_Data!C6))),"Unknown") -> Male | E6: =IF(ISNUMBER(Raw_Data!D6),Raw_Data!D6,IFERROR(DATEVALUE(Raw_Data!D6),"")) -> 36155 | F6: =IF(TRIM(CLEAN(Raw_Data!E6))="","Not Provided",TRIM(CLEAN(Raw_Data!E6))) -> 1149528740 | G6: =IF(TRIM(CLEAN(Raw_Data!F6))="","Not Provided",LOWER(TRIM(CLEAN(Raw_Data!F6)))) -> hussein.lotfy80@gmail.com | H6: =IF(TRIM(CLEAN(Raw_Data!G6))="","Not Provided",PROPER(TRIM(CLEAN(Raw_Data!G6)))) -> Tanta | I6: =IF(TRIM(CLEAN(Raw_Data!H6))="","Not Provided",PROPER(TRIM(CLEAN(Raw_Data!H6)))) -> Nile Delta | J6: =IF(OR(PROPER(TRIM(CLEAN(Raw_Data!I6)))="Bronze",PROPER(TRIM(CLEAN(Raw_Data!I6)))="Silver",PROPER(TRIM(CLEAN(Raw_Data!I6)))="Gold"),PROPER(TRIM(CLEAN(Raw_Data!I6))),"Unknown") -> Gold | K6: =IF(ISNUMBER(Raw_Data!J6),Raw_Data!J6,IFERROR(DATEVALUE(Raw_Data!J6),"")) -> 44839 | L6: =IFERROR(MID(G6,FIND("@",G6)+1,99),"") -> gmail.com | M6: =LEFT(B6,3) -> CUS | N6: =IFERROR(MID(B6,4,10),"") -> 02664 | O6: =RIGHT(F6,4) -> 8740 | P6: =CONCATENATE(C6," - ",J6) -> Hussein Lotfy - Gold | Q6: =IF(B6="","Remove - missing ID",IF(OR(E6="",K6=""),"Remove - invalid date",IF(COUNTIF($B$2:B6,B6)>1,"Remove - duplicate ID","Keep"))) -> Keep | R6: =IF(Q6="Keep","Yes","No") -> Yes
A7: =ROW(Raw_Data!A7) -> 7 | B7: =TRIM(CLEAN(Raw_Data!A7)) -> CUS01174 | C7: =IF(TRIM(CLEAN(Raw_Data!B7))="","Not Provided",PROPER(TRIM(CLEAN(Raw_Data!B7)))) -> Nour Mostafa | D7: =IF(OR(PROPER(TRIM(CLEAN(Raw_Data!C7)))="Male",PROPER(TRIM(CLEAN(Raw_Data!C7)))="Female"),PROPER(TRIM(CLEAN(Raw_Data!C7))),"Unknown") -> Female | E7: =IF(ISNUMBER(Raw_Data!D7),Raw_Data!D7,IFERROR(DATEVALUE(Raw_Data!D7),"")) -> 30843 | F7: =IF(TRIM(CLEAN(Raw_Data!E7))="","Not Provided",TRIM(CLEAN(Raw_Data!E7))) -> 1114481563 | G7: =IF(TRIM(CLEAN(Raw_Data!F7))="","Not Provided",LOWER(TRIM(CLEAN(Raw_Data!F7)))) -> nour.mostafa72@hotmail.com | H7: =IF(TRIM(CLEAN(Raw_Data!G7))="","Not Provided",PROPER(TRIM(CLEAN(Raw_Data!G7)))) -> Cairo | I7: =IF(TRIM(CLEAN(Raw_Data!H7))="","Not Provided",PROPER(TRIM(CLEAN(Raw_Data!H7)))) -> Greater Cairo | J7: =IF(OR(PROPER(TRIM(CLEAN(Raw_Data!I7)))="Bronze",PROPER(TRIM(CLEAN(Raw_Data!I7)))="Silver",PROPER(TRIM(CLEAN(Raw_Data!I7)))="Gold"),PROPER(TRIM(CLEAN(Raw_Data!I7))),"Unknown") -> Silver | K7: =IF(ISNUMBER(Raw_Data!J7),Raw_Data!J7,IFERROR(DATEVALUE(Raw_Data!J7),"")) -> 44476 | L7: =IFERROR(MID(G7,FIND("@",G7)+1,99),"") -> hotmail.com | M7: =LEFT(B7,3) -> CUS | N7: =IFERROR(MID(B7,4,10),"") -> 01174 | O7: =RIGHT(F7,4) -> 1563 | P7: =CONCATENATE(C7," - ",J7) -> Nour Mostafa - Silver | Q7: =IF(B7="","Remove - missing ID",IF(OR(E7="",K7=""),"Remove - invalid date",IF(COUNTIF($B$2:B7,B7)>1,"Remove - duplicate ID","Keep"))) -> Keep | R7: =IF(Q7="Keep","Yes","No") -> Yes
A8: =ROW(Raw_Data!A8) -> 8 | B8: =TRIM(CLEAN(Raw_Data!A8)) -> CUS02677 | C8: =IF(TRIM(CLEAN(Raw_Data!B8))="","Not Provided",PROPER(TRIM(CLEAN(Raw_Data!B8)))) -> Hazem Hamdy | D8: =IF(OR(PROPER(TRIM(CLEAN(Raw_Data!C8)))="Male",PROPER(TRIM(CLEAN(Raw_Data!C8)))="Female"),PROPER(TRIM(CLEAN(Raw_Data!C8))),"Unknown") -> Male | E8: =IF(ISNUMBER(Raw_Data!D8),Raw_Data!D8,IFERROR(DATEVALUE(Raw_Data!D8),"")) -> 27297 | F8: =IF(TRIM(CLEAN(Raw_Data!E8))="","Not Provided",TRIM(CLEAN(Raw_Data!E8))) -> 1084698064 | G8: =IF(TRIM(CLEAN(Raw_Data!F8))="","Not Provided",LOWER(TRIM(CLEAN(Raw_Data!F8)))) -> hazem.hamdy68@outlook.com | H8: =IF(TRIM(CLEAN(Raw_Data!G8))="","Not Provided",PROPER(TRIM(CLEAN(Raw_Data!G8)))) -> Giza | I8: =IF(TRIM(CLEAN(Raw_Data!H8))="","Not Provided",PROPER(TRIM(CLEAN(Raw_Data!H8)))) -> Greater Cairo | J8: =IF(OR(PROPER(TRIM(CLEAN(Raw_Data!I8)))="Bronze",PROPER(TRIM(CLEAN(Raw_Data!I8)))="Silver",PROPER(TRIM(CLEAN(Raw_Data!I8)))="Gold"),PROPER(TRIM(CLEAN(Raw_Data!I8))),"Unknown") -> Bronze | K8: =IF(ISNUMBER(Raw_Data!J8),Raw_Data!J8,IFERROR(DATEVALUE(Raw_Data!J8),"")) -> 43858 | L8: =IFERROR(MID(G8,FIND("@",G8)+1,99),"") -> outlook.com | M8: =LEFT(B8,3) -> CUS | N8: =IFERROR(MID(B8,4,10),"") -> 02677 | O8: =RIGHT(F8,4) -> 8064 | P8: =CONCATENATE(C8," - ",J8) -> Hazem Hamdy - Bronze | Q8: =IF(B8="","Remove - missing ID",IF(OR(E8="",K8=""),"Remove - invalid date",IF(COUNTIF($B$2:B8,B8)>1,"Remove - duplicate ID","Keep"))) -> Keep | R8: =IF(Q8="Keep","Yes","No") -> Yes
A9: =ROW(Raw_Data!A9) -> 9 | B9: =TRIM(CLEAN(Raw_Data!A9)) -> CUS01028 | C9: =IF(TRIM(CLEAN(Raw_Data!B9))="","Not Provided",PROPER(TRIM(CLEAN(Raw_Data!B9)))) -> Fatima Ramadan | D9: =IF(OR(PROPER(TRIM(CLEAN(Raw_Data!C9)))="Male",PROPER(TRIM(CLEAN(Raw_Data!C9)))="Female"),PROPER(TRIM(CLEAN(Raw_Data!C9))),"Unknown") -> Female | E9: =IF(ISNUMBER(Raw_Data!D9),Raw_Data!D9,IFERROR(DATEVALUE(Raw_Data!D9),"")) -> 27687 | F9: =IF(TRIM(CLEAN(Raw_Data!E9))="","Not Provided",TRIM(CLEAN(Raw_Data!E9))) -> 1019232076 | G9: =IF(TRIM(CLEAN(Raw_Data!F9))="","Not Provided",LOWER(TRIM(CLEAN(Raw_Data!F9)))) -> fatima.ramadan42@outlook.com | H9: =IF(TRIM(CLEAN(Raw_Data!G9))="","Not Provided",PROPER(TRIM(CLEAN(Raw_Data!G9)))) -> Aswan | I9: =IF(TRIM(CLEAN(Raw_Data!H9))="","Not Provided",PROPER(TRIM(CLEAN(Raw_Data!H9)))) -> Upper Egypt | J9: =IF(OR(PROPER(TRIM(CLEAN(Raw_Data!I9)))="Bronze",PROPER(TRIM(CLEAN(Raw_Data!I9)))="Silver",PROPER(TRIM(CLEAN(Raw_Data!I9)))="Gold"),PROPER(TRIM(CLEAN(Raw_Data!I9))),"Unknown") -> Bronze | K9: =IF(ISNUMBER(Raw_Data!J9),Raw_Data!J9,IFERROR(DATEVALUE(Raw_Data!J9),"")) -> 45019 | L9: =IFERROR(MID(G9,FIND("@",G9)+1,99),"") -> outlook.com | M9: =LEFT(B9,3) -> CUS | N9: =IFERROR(MID(B9,4,10),"") -> 01028 | O9: =RIGHT(F9,4) -> 2076 | P9: =CONCATENATE(C9," - ",J9) -> Fatima Ramadan - Bronze | Q9: =IF(B9="","Remove - missing ID",IF(OR(E9="",K9=""),"Remove - invalid date",IF(COUNTIF($B$2:B9,B9)>1,"Remove - duplicate ID","Keep"))) -> Keep | R9: =IF(Q9="Keep","Yes","No") -> Yes
A10: =ROW(Raw_Data!A10) -> 10 | B10: =TRIM(CLEAN(Raw_Data!A10)) -> CUS02084 | C10: =IF(TRIM(CLEAN(Raw_Data!B10))="","Not Provided",PROPER(TRIM(CLEAN(Raw_Data!B10)))) -> Ramy Farouk | D10: =IF(OR(PROPER(TRIM(CLEAN(Raw_Data!C10)))="Male",PROPER(TRIM(CLEAN(Raw_Data!C10)))="Female"),PROPER(TRIM(CLEAN(Raw_Data!C10))),"Unknown") -> Male | E10: =IF(ISNUMBER(Raw_Data!D10),Raw_Data!D10,IFERROR(DATEVALUE(Raw_Data!D10),"")) | F10: =IF(TRIM(CLEAN(Raw_Data!E10))="","Not Provided",TRIM(CLEAN(Raw_Data!E10))) -> 1069113227 | G10: =IF(TRIM(CLEAN(Raw_Data!F10))="","Not Provided",LOWER(TRIM(CLEAN(Raw_Data!F10)))) -> Not Provided | H10: =IF(TRIM(CLEAN(Raw_Data!G10))="","Not Provided",PROPER(TRIM(CLEAN(Raw_Data!G10)))) -> Suez | I10: =IF(TRIM(CLEAN(Raw_Data!H10))="","Not Provided",PROPER(TRIM(CLEAN(Raw_Data!H10)))) -> Canal Zone | J10: =IF(OR(PROPER(TRIM(CLEAN(Raw_Data!I10)))="Bronze",PROPER(TRIM(CLEAN(Raw_Data!I10)))="Silver",PROPER(TRIM(CLEAN(Raw_Data!I10)))="Gold"),PROPER(TRIM(CLEAN(Raw_Data!I10))),"Unknown") -> Silver | K10: =IF(ISNUMBER(Raw_Data!J10),Raw_Data!J10,IFERROR(DATEVALUE(Raw_Data!J10),"")) -> 44448 | L10: =IFERROR(MID(G10,FIND("@",G10)+1,99),"") | M10: =LEFT(B10,3) -> CUS | N10: =IFERROR(MID(B10,4,10),"") -> 02084 | O10: =RIGHT(F10,4) -> 3227 | P10: =CONCATENATE(C10," - ",J10) -> Ramy Farouk - Silver | Q10: =IF(B10="","Remove - missing ID",IF(OR(E10="",K10=""),"Remove - invalid date",IF(COUNTIF($B$2:B10,B10)>1,"Remove - duplicate ID","Keep"))) -> Remove - invalid date | R10: =IF(Q10="Keep","Yes","No") -> No
A11: =ROW(Raw_Data!A11) -> 11 | B11: =TRIM(CLEAN(Raw_Data!A11)) -> CUS01445 | C11: =IF(TRIM(CLEAN(Raw_Data!B11))="","Not Provided",PROPER(TRIM(CLEAN(Raw_Data!B11)))) -> Sherif Zaki | D11: =IF(OR(PROPER(TRIM(CLEAN(Raw_Data!C11)))="Male",PROPER(TRIM(CLEAN(Raw_Data!C11)))="Female"),PROPER(TRIM(CLEAN(Raw_Data!C11))),"Unknown") -> Male | E11: =IF(ISNUMBER(Raw_Data!D11),Raw_Data!D11,IFERROR(DATEVALUE(Raw_Data!D11),"")) -> 33609 | F11: =IF(TRIM(CLEAN(Raw_Data!E11))="","Not Provided",TRIM(CLEAN(Raw_Data!E11))) -> Not Provided | G11: =IF(TRIM(CLEAN(Raw_Data!F11))="","Not Provided",LOWER(TRIM(CLEAN(Raw_Data!F11)))) -> sherif.zaki7@hotmail.com | H11: =IF(TRIM(CLEAN(Raw_Data!G11))="","Not Provided",PROPER(TRIM(CLEAN(Raw_Data!G11)))) -> Luxor | I11: =IF(TRIM(CLEAN(Raw_Data!H11))="","Not Provided",PROPER(TRIM(CLEAN(Raw_Data!H11)))) -> Upper Egypt | J11: =IF(OR(PROPER(TRIM(CLEAN(Raw_Data!I11)))="Bronze",PROPER(TRIM(CLEAN(Raw_Data!I11)))="Silver",PROPER(TRIM(CLEAN(Raw_Data!I11)))="Gold"),PROPER(TRIM(CLEAN(Raw_Data!I11))),"Unknown") -> Silver | K11: =IF(ISNUMBER(Raw_Data!J11),Raw_Data!J11,IFERROR(DATEVALUE(Raw_Data!J11),"")) -> 44129 | L11: =IFERROR(MID(G11,FIND("@",G11)+1,99),"") -> hotmail.com | M11: =LEFT(B11,3) -> CUS | N11: =IFERROR(MID(B11,4,10),"") -> 01445 | O11: =RIGHT(F11,4) -> ided | P11: =CONCATENATE(C11," - ",J11) -> Sherif Zaki - Silver | Q11: =IF(B11="","Remove - missing ID",IF(OR(E11="",K11=""),"Remove - invalid date",IF(COUNTIF($B$2:B11,B11)>1,"Remove - duplicate ID","Keep"))) -> Keep | R11: =IF(Q11="Keep","Yes","No") -> Yes
A12: =ROW(Raw_Data!A12) -> 12 | B12: =TRIM(CLEAN(Raw_Data!A12)) -> CUS00933 | C12: =IF(TRIM(CLEAN(Raw_Data!B12))="","Not Provided",PROPER(TRIM(CLEAN(Raw_Data!B12)))) -> Not Provided | D12: =IF(OR(PROPER(TRIM(CLEAN(Raw_Data!C12)))="Male",PROPER(TRIM(CLEAN(Raw_Data!C12)))="Female"),PROPER(TRIM(CLEAN(Raw_Data!C12))),"Unknown") -> Male | E12: =IF(ISNUMBER(Raw_Data!D12),Raw_Data!D12,IFERROR(DATEVALUE(Raw_Data!D12),"")) -> 33225 | F12: =IF(TRIM(CLEAN(Raw_Data!E12))="","Not Provided",TRIM(CLEAN(Raw_Data!E12))) -> 1229438263 | G12: =IF(TRIM(CLEAN(Raw_Data!F12))="","Not Provided",LOWER(TRIM(CLEAN(Raw_Data!F12)))) -> bassem.farouk40@gmail.com | H12: =IF(TRIM(CLEAN(Raw_Data!G12))="","Not Provided",PROPER(TRIM(CLEAN(Raw_Data!G12)))) -> Ismailia | I12: =IF(TRIM(CLEAN(Raw_Data!H12))="","Not Provided",PROPER(TRIM(CLEAN(Raw_Data!H12)))) -> Canal Zone | J12: =IF(OR(PROPER(TRIM(CLEAN(Raw_Data!I12)))="Bronze",PROPER(TRIM(CLEAN(Raw_Data!I12)))="Silver",PROPER(TRIM(CLEAN(Raw_Data!I12)))="Gold"),PROPER(TRIM(CLEAN(Raw_Data!I12))),"Unknown") -> Silver | K12: =IF(ISNUMBER(Raw_Data!J12),Raw_Data!J12,IFERROR(DATEVALUE(Raw_Data!J12),"")) -> 44191 | L12: =IFERROR(MID(G12,FIND("@",G12)+1,99),"") -> gmail.com | M12: =LEFT(B12,3) -> CUS | N12: =IFERROR(MID(B12,4,10),"") -> 00933 | O12: =RIGHT(F12,4) -> 8263 | P12: =CONCATENATE(C12," - ",J12) -> Not Provided - Silver | Q12: =IF(B12="","Remove - missing ID",IF(OR(E12="",K12=""),"Remove - invalid date",IF(COUNTIF($B$2:B12,B12)>1,"Remove - duplicate ID","Keep"))) -> Keep | R12: =IF(Q12="Keep","Yes","No") -> Yes
A13: =ROW(Raw_Data!A13) -> 13 | B13: =TRIM(CLEAN(Raw_Data!A13)) -> CUS00179 | C13: =IF(TRIM(CLEAN(Raw_Data!B13))="","Not Provided",PROPER(TRIM(CLEAN(Raw_Data!B13)))) -> Hossam Fathy | D13: =IF(OR(PROPER(TRIM(CLEAN(Raw_Data!C13)))="Male",PROPER(TRIM(CLEAN(Raw_Data!C13)))="Female"),PROPER(TRIM(CLEAN(Raw_Data!C13))),"Unknown") -> Male | E13: =IF(ISNUMBER(Raw_Data!D13),Raw_Data!D13,IFERROR(DATEVALUE(Raw_Data!D13),"")) -> 29867 | F13: =IF(TRIM(CLEAN(Raw_Data!E13))="","Not Provided",TRIM(CLEAN(Raw_Data!E13))) -> 1248988647 | G13: =IF(TRIM(CLEAN(Raw_Data!F13))="","Not Provided",LOWER(TRIM(CLEAN(Raw_Data!F13)))) -> hossam.fathy16@yahoo.com | H13: =IF(TRIM(CLEAN(Raw_Data!G13))="","Not Provided",PROPER(TRIM(CLEAN(Raw_Data!G13)))) -> Port Said | I13: =IF(TRIM(CLEAN(Raw_Data!H13))="","Not Provided",PROPER(TRIM(CLEAN(Raw_Data!H13)))) -> Not Provided | J13: =IF(OR(PROPER(TRIM(CLEAN(Raw_Data!I13)))="Bronze",PROPER(TRIM(CLEAN(Raw_Data!I13)))="Silver",PROPER(TRIM(CLEAN(Raw_Data!I13)))="Gold"),PROPER(TRIM(CLEAN(Raw_Data!I13))),"Unknown") -> Bronze | K13: =IF(ISNUMBER(Raw_Data!J13),Raw_Data!J13,IFERROR(DATEVALUE(Raw_Data!J13),"")) -> 45109 | L13: =IFERROR(MID(G13,FIND("@",G13)+1,99),"") -> yahoo.com | M13: =LEFT(B13,3) -> CUS | N13: =IFERROR(MID(B13,4,10),"") -> 00179 | O13: =RIGHT(F13,4) -> 8647 | P13: =CONCATENATE(C13," - ",J13) -> Hossam Fathy - Bronze | Q13: =IF(B13="","Remove - missing ID",IF(OR(E13="",K13=""),"Remove - invalid date",IF(COUNTIF($B$2:B13,B13)>1,"Remove - duplicate ID","Keep"))) -> Keep | R13: =IF(Q13="Keep","Yes","No") -> Yes
... A166: =ROW(Raw_Data!A166) -> 166 | B166: =TRIM(CLEAN(Raw_Data!A166)) | C166: =IF(TRIM(CLEAN(Raw_Data!B166))="","Not Provided",PROPER(TRIM(CLEAN(Raw_Data!B166)))) -> Dina Attia | D166: =IF(OR(PROPER(TRIM(CLEAN(Raw_Data!C166)))="Male",PROPER(TRIM(CLEAN(Raw_Data!C166)))="Female"),PROPER(TRIM(CLEAN(Raw_Data!C166))),"Unknown") -> Female | E166: =IF(ISNUMBER(Raw_Data!D166),Raw_Data!D166,IFERROR(DATEVALUE(Raw_Data!D166),"")) -> 28548 | F166: =IF(TRIM(CLEAN(Raw_Data!E166))="","Not Provided",TRIM(CLEAN(Raw_Data!E166))) -> 1272850928 | G166: =IF(TRIM(CLEAN(Raw_Data!F166))="","Not Provided",LOWER(TRIM(CLEAN(Raw_Data!F166)))) -> dina.attia61@yahoo.com | H166: =IF(TRIM(CLEAN(Raw_Data!G166))="","Not Provided",PROPER(TRIM(CLEAN(Raw_Data!G166)))) -> Alexandria | I166: =IF(TRIM(CLEAN(Raw_Data!H166))="","Not Provided",PROPER(TRIM(CLEAN(Raw_Data!H166)))) -> Alexandria | J166: =IF(OR(PROPER(TRIM(CLEAN(Raw_Data!I166)))="Bronze",PROPER(TRIM(CLEAN(Raw_Data!I166)))="Silver",PROPER(TRIM(CLEAN(Raw_Data!I166)))="Gold"),PROPER(TRIM(CLEAN(Raw_Data!I166))),"Unknown") -> Gold | K166: =IF(ISNUMBER(Raw_Data!J166),Raw_Data!J166,IFERROR(DATEVALUE(Raw_Data!J166),"")) -> 44283 | L166: =IFERROR(MID(G166,FIND("@",G166)+1,99),"") -> yahoo.com | M166: =LEFT(B166,3) | N166: =IFERROR(MID(B166,4,10),"") | O166: =RIGHT(F166,4) -> 0928 | P166: =CONCATENATE(C166," - ",J166) -> Dina Attia - Gold | Q166: =IF(B166="","Remove - missing ID",IF(OR(E166="",K166=""),"Remove - invalid date",IF(COUNTIF($B$2:B166,B166)>1,"Remove - duplicate ID","Keep"))) -> Remove - missing ID | R166: =IF(Q166="Keep","Yes","No") -> No

Sheet Data_Quality_Check
A1: Data Quality Check – Formula Based
A3: Summary Metric | B3: Before | C3: After | D3: Status
A4: Total Raw Rows | B4: =COUNTA(Raw_Data!C:C)-1 -> 165 | C4: =COUNTIF(tblCleanFormula[Keep_Record],"Yes") -> 135 | D4: Formula
A5: Rows Kept | B5: =COUNTIF(tblCleanFormula[Keep_Record],"Yes") -> 135 | C5: =COUNTIF(tblCleanFormula[Keep_Record],"Yes") -> 135 | D5: Formula
A6: Duplicate Rows Found | B6: 10 | C6: 0 | D6: Cleaned by flag
A7: Missing Values Found | B7: 38 | C7: 0 | D7: Handled by formula
A8: Invalid Records Found | B8: 2 | C8: 0 | D8: Flagged
A9: Rows Removed | B9: =B4-C4 -> 30 | C9: 0 | D9: Calculated
A10: Rows Corrected | B10: 38 | C10: 0 | D10: Standardized
A13: Issue | B13: Before | C13: After | D13: Status
A14: Duplicate Records | B14: 10 | C14: 0 | D14: Clean
A15: Blank / Null Values | B15: 38 | C15: 0 | D15: Handled
A16: Invalid Customer ID | B16: 2 | C16: 0 | D16: Flagged
A17: Invalid Date Values | B17: 29 | C17: 0 | D17: Flagged
A18: Inconsistent Gender / Tier | B18: 4 | C18: 0 | D18: Standardized
A19: Extra Spaces | B19: 4 | C19: 0 | D19: Trimmed
